<?xml version="1.0" encoding="utf-8"?>
<!-- This URDF was automatically created by SolidWorks to URDF Exporter! Originally created by Stephen Brawner (brawner@gmail.com) 
     Commit Version: 1.6.0-4-g7f85cfe  Build Version: 1.6.7995.38578
     For more information, please see http://wiki.ros.org/sw_urdf_exporter -->
<robot
  name="fudan_humanoid">
  <link
    name="base_link">
    <inertial>
      <origin
        xyz="0.00053443 0.0058502 0.12545"
        rpy="0 0 0" />
      <mass
        value="27.766" />
      <inertia
        ixx="1.422586406"
        ixy="3.9565E-05"
        ixz="0.00055654"
        iyy="1.039829852"
        iyz="1.314E-06"
        izz="0.468104445" />
    </inertial>
    <visual>
      <origin
        xyz="0 0 0"
        rpy="0 0 0" />
      <geometry>
        <mesh
          filename="../meshes/base_link.STL" />
      </geometry>
      <material
        name="">
        <color
          rgba="0.89804 0.91765 0.92941 1" />
      </material>
    </visual>
    <collision>
      <origin
        xyz="0 0. 0.1"
        rpy="0 0 0" />
      <geometry>
        <box size="0.4 0.4 0.4"/>
      </geometry>
    </collision>
  </link>
  <link
    name="left_leg_pitch_link">
    <inertial>
      <origin
        xyz="-0.063328 0.10996 -0.062867"
        rpy="0 0 0" />
      <mass
        value="1.535" />
      <inertia
        ixx="0.0021494"
        ixy="0.0001925"
        ixz="-0.00011127"
        iyy="0.0016183"
        iyz="-2.6116E-06"
        izz="0.0016106" />
    </inertial>
    <visual>
      <origin
        xyz="0 0 0"
        rpy="0 0 0" />
      <geometry>
        <mesh
          filename="../meshes/left_leg_pitch_link.STL" />
      </geometry>
      <material
        name="">
        <color
          rgba="0.89804 0.91765 0.92941 1" />
      </material>
    </visual>
    <!-- <collision>
      <origin
        xyz="0 0 0"
        rpy="0 0 0" />
      <geometry>
        <mesh
          filename="../meshes/left_leg_pitch_link.STL" />
      </geometry>
    </collision> -->
  </link>
  <joint
    name="left_leg_pitch_joint"
    type="revolute">
    <origin
      xyz="0 0.026488 -0.116"
      rpy="0 0 0" />
    <parent
      link="base_link" />
    <child
      link="left_leg_pitch_link" />
    <axis
      xyz="0 -0.86603 0.5" />
    <limit
      lower="-0.88"
      upper="0.88"
      effort="250"
      velocity="9" />
  </joint>
  <link
    name="left_leg_roll_link">
    <inertial>
      <origin
        xyz="-0.057621 1.1621E-05 -0.0047639"
        rpy="0 0 0" />
      <mass
        value="1.0891" />
      <inertia
        ixx="0.00069767"
        ixy="4.0437E-07"
        ixz="5.5106E-07"
        iyy="0.00089617"
        iyz="-2.5353E-08"
        izz="0.001386" />
    </inertial>
    <visual>
      <origin
        xyz="0 0 0"
        rpy="0 0 0" />
      <geometry>
        <mesh
          filename="../meshes/left_leg_roll_link.STL" />
      </geometry>
      <material
        name="">
        <color
          rgba="0.79216 0.81961 0.93333 1" />
      </material>
    </visual>
    <!-- <collision>
      <origin
        xyz="0 0 0"
        rpy="0 0 0" />
      <geometry>
        <mesh
          filename="../meshes/left_leg_roll_link.STL" />
      </geometry>
    </collision> -->
  </link>
  <joint
    name="left_leg_roll_joint"
    type="revolute">
    <origin
      xyz="0.0579 0.11951 -0.069"
      rpy="0 0 0" />
    <parent
      link="left_leg_pitch_link" />
    <child
      link="left_leg_roll_link" />
    <axis
      xyz="1 0 0" />
    <limit
      lower="-0.2"
      upper="0.5"
      effort="100"
      velocity="9" />
  </joint>
  <link
    name="left_leg_yaw_link">
    <inertial>
      <origin
        xyz="0.00043634 0.0017182 -0.20249"
        rpy="0 0 0" />
      <mass
        value="3.6405" />
      <inertia
        ixx="0.013557"
        ixy="1.1779E-05"
        ixz="-3.6177E-05"
        iyy="0.017913"
        iyz="0.00028874"
        izz="0.00518" />
    </inertial>
    <visual>
      <origin
        xyz="0 0 0"
        rpy="0 0 0" />
      <geometry>
        <mesh
          filename="../meshes/left_leg_yaw_link.STL" />
      </geometry>
      <material
        name="">
        <color
          rgba="0.79216 0.81961 0.93333 1" />
      </material>
    </visual>
    <!-- <collision>
      <origin
        xyz="0 0 0"
        rpy="0 0 0" />
      <geometry>
        <mesh
          filename="../meshes/left_leg_yaw_link.STL" />
      </geometry>
    </collision> -->
  </link>
  <joint
    name="left_leg_yaw_joint"
    type="revolute">
    <origin
      xyz="-0.0579 0 0.0351"
      rpy="0 0 0" />
    <parent
      link="left_leg_roll_link" />
    <child
      link="left_leg_yaw_link" />
    <axis
      xyz="0 0 1" />
    <limit
      lower="-1.05"
      upper="1.05"
      effort="100"
      velocity="9" />
  </joint>
  <link
    name="left_knee_link">
    <inertial>
      <origin
        xyz="0.0035379 -0.030016 -0.12582"
        rpy="0 0 0" />
      <mass
        value="2.7384" />
      <inertia
        ixx="0.018175"
        ixy="-3.7288E-06"
        ixz="0.00066617"
        iyy="0.019344"
        iyz="-1.8579E-05"
        izz="0.0016643" />
    </inertial>
    <visual>
      <origin
        xyz="0 0 0"
        rpy="0 0 0" />
      <geometry>
        <mesh
          filename="../meshes/left_knee_link.STL" />
      </geometry>
      <material
        name="">
        <color
          rgba="0.89804 0.91765 0.92941 1" />
      </material>
    </visual>
    <!-- <collision>
      <origin
        xyz="0 0 0"
        rpy="0 0 0" />
      <geometry>
        <mesh
          filename="../meshes/left_knee_link.STL" />
      </geometry>
    </collision> -->
  </link>
  <joint
    name="left_knee_joint"
    type="revolute">
    <origin
      xyz="0 0.02 -0.4151"
      rpy="0 0 0" />
    <parent
      link="left_leg_yaw_link" />
    <child
      link="left_knee_link" />
    <axis
      xyz="0 1 0" />
    <limit
      lower="-0.7"
      upper="1.5"
      effort="250"
      velocity="9" />
  </joint>
  <link
    name="left_ankle_pitch_link">
    <inertial>
      <origin
        xyz="1.2848E-09 -0.0307 -2.8828E-10"
        rpy="0 0 0" />
      <mass
        value="0.10749" />
      <inertia
        ixx="1.4354E-05"
        ixy="2.6541E-14"
        ixz="-6.658E-13"
        iyy="1.4339E-05"
        iyz="-6.3545E-13"
        izz="1.6257E-05" />
    </inertial>
    <visual>
      <origin
        xyz="0 0 0"
        rpy="0 0 0" />
      <geometry>
        <mesh
          filename="../meshes/left_ankle_pitch_link.STL" />
      </geometry>
      <material
        name="">
        <color
          rgba="0.89804 0.91765 0.92941 1" />
      </material>
    </visual>
    <!-- <collision>
      <origin
        xyz="0 0 0"
        rpy="0 0 0" />
      <geometry>
        <mesh
          filename="../meshes/left_ankle_pitch_link.STL" />
      </geometry>
    </collision> -->
  </link>
  <joint
    name="left_ankle_pitch_joint"
    type="revolute">
    <origin
      xyz="0.015 0.0007 -0.37"
      rpy="0 0 0" />
    <parent
      link="left_knee_link" />
    <child
      link="left_ankle_pitch_link" />
    <axis
      xyz="0 1 0" />
    <limit
      lower="-0.7"
      upper="0.87"
      effort="100"
      velocity="9" />
    <dynamics
      friction="0.1" />
  </joint>
  <link
    name="left_ankle_roll_link">
    <inertial>
      <origin
        xyz="-0.0307 0.00016219 -0.027162"
        rpy="0 0 0" />
      <mass
        value="0.14038" />
      <inertia
        ixx="5.7884E-05"
        ixy="-5.1703E-11"
        ixz="4.1473E-10"
        iyy="9.3946E-05"
        iyz="1.0763E-07"
        izz="7.4507E-05" />
    </inertial>
    <visual>
      <origin
        xyz="0 0 0"
        rpy="0 0 0" />
      <geometry>
        <mesh
          filename="../meshes/left_ankle_roll_link.STL" />
      </geometry>
      <material
        name="">
        <color
          rgba="0.89804 0.91765 0.92941 1" />
      </material>
    </visual>
    <!-- <collision>
      <origin
        xyz="0 0 0"
        rpy="0 0 0" />
      <geometry>
        <mesh
          filename="../meshes/left_ankle_roll_link.STL" />
      </geometry>
    </collision> -->
  </link>
  <joint
    name="left_ankle_roll_joint"
    type="revolute">
    <origin
      xyz="0.0307 -0.0307 0"
      rpy="0 0 0" />
    <parent
      link="left_ankle_pitch_link" />
    <child
      link="left_ankle_roll_link" />
    <axis
      xyz="1 0 0" />
    <limit
      lower="-0.5"
      upper="0.5"
      effort="100"
      velocity="9" />
    <dynamics
      friction="0.1" />
  </joint>
  <link
    name="L_foot">
    <inertial>
      <origin
        xyz="0.016486 -3.9561E-06 0.0059825"
        rpy="0 0 0" />
      <mass
        value="0.58366" />
      <inertia
        ixx="0.00043428"
        ixy="2.1966E-07"
        ixz="1.6375E-06"
        iyy="0.0025408"
        iyz="1.4886E-09"
        izz="0.0029617" />
    </inertial>
    <visual>
      <origin
        xyz="0 0 0"
        rpy="0 0 0" />
      <geometry>
        <mesh
          filename="../meshes/L_foot.STL" />
      </geometry>
      <material
        name="">
        <color
          rgba="0.89804 0.91765 0.92941 1" />
      </material>
    </visual>
    <collision>
      <origin
        xyz="0.07 0.0 0.0"
        rpy="0 0 0" />
      <geometry>
        <box size="0.35 0.10 0.02"/>
      </geometry>
    </collision>
  </link>
  <joint
    name="L_foot_joint"
    type="fixed">
    <origin
      xyz="-0.0307 0 -0.073"
      rpy="0 0 0" />
    <parent
      link="left_ankle_roll_link" />
    <child
      link="L_foot" />
    <axis
      xyz="0 0 0" />
  </joint>
  <link
    name="right_leg_pitch_link">
    <inertial>
      <origin
        xyz="-0.063818 -0.10945 -0.063361"
        rpy="0 0 0" />
      <mass
        value="1.6695" />
      <inertia
        ixx="0.002191"
        ixy="-0.00019305"
        ixz="-0.00011127"
        iyy="0.0016407"
        iyz="1.5741E-06"
        izz="0.001633" />
    </inertial>
    <visual>
      <origin
        xyz="0 0 0"
        rpy="0 0 0" />
      <geometry>
        <mesh
          filename="../meshes/right_leg_pitch_link.STL" />
      </geometry>
      <material
        name="">
        <color
          rgba="0.89804 0.91765 0.92941 1" />
      </material>
    </visual>
    <!-- <collision>
      <origin
        xyz="0 0 0"
        rpy="0 0 0" />
      <geometry>
        <mesh
          filename="../meshes/right_leg_pitch_link.STL" />
      </geometry>
    </collision> -->
  </link>
  <joint
    name="right_leg_pitch_joint"
    type="revolute">
    <origin
      xyz="0 -0.026488 -0.116"
      rpy="0 0 0" />
    <parent
      link="base_link" />
    <child
      link="right_leg_pitch_link" />
    <axis
      xyz="0 0.86603 0.5" />
    <limit
      lower="-0.88"
      upper="0.88"
      effort="250"
      velocity="9" />
  </joint>
  <link
    name="right_leg_roll_link">
    <inertial>
      <origin
        xyz="-0.057754 -1.1883E-05 -0.0047639"
        rpy="0 0 0" />
      <mass
        value="1.0891" />
      <inertia
        ixx="0.00069767"
        ixy="4.0437E-07"
        ixz="8.7519E-07"
        iyy="0.00089617"
        iyz="2.1334E-08"
        izz="0.001386" />
    </inertial>
    <visual>
      <origin
        xyz="0 0 0"
        rpy="0 0 0" />
      <geometry>
        <mesh
          filename="../meshes/right_leg_roll_link.STL" />
      </geometry>
      <material
        name="">
        <color
          rgba="0.79216 0.81961 0.93333 1" />
      </material>
    </visual>
    <!-- <collision>
      <origin
        xyz="0 0 0"
        rpy="0 0 0" />
      <geometry>
        <mesh
          filename="../meshes/right_leg_roll_link.STL" />
      </geometry>
    </collision> -->
  </link>
  <joint
    name="right_leg_roll_joint"
    type="revolute">
    <origin
      xyz="0.0579 -0.11951 -0.069"
      rpy="0 0 0" />
    <parent
      link="right_leg_pitch_link" />
    <child
      link="right_leg_roll_link" />
    <axis
      xyz="1 0 0" />
    <limit
      lower="-0.2"
      upper="0.5"
      effort="100"
      velocity="9" />
  </joint>
  <link
    name="right_leg_yaw_link">
    <inertial>
      <origin
        xyz="0.00043958 -0.0017182 -0.20225"
        rpy="0 0 0" />
      <mass
        value="3.6408" />
      <inertia
        ixx="0.01356"
        ixy="-1.1554E-05"
        ixz="-3.4598E-05"
        iyy="0.017916"
        iyz="-0.00028693"
        izz="0.00518" />
    </inertial>
    <visual>
      <origin
        xyz="0 0 0"
        rpy="0 0 0" />
      <geometry>
        <mesh
          filename="../meshes/right_leg_yaw_link.STL" />
      </geometry>
      <material
        name="">
        <color
          rgba="0.79216 0.81961 0.93333 1" />
      </material>
    </visual>
    <!-- <collision>
      <origin
        xyz="0 0 0"
        rpy="0 0 0" />
      <geometry>
        <mesh
          filename="../meshes/right_leg_yaw_link.STL" />
      </geometry>
    </collision> -->
  </link>
  <joint
    name="right_leg_yaw_joint"
    type="revolute">
    <origin
      xyz="-0.0579 0 0.0351"
      rpy="0 0 0" />
    <parent
      link="right_leg_roll_link" />
    <child
      link="right_leg_yaw_link" />
    <axis
      xyz="0 0 1" />
    <limit
      lower="-1.05"
      upper="1.05"
      effort="100"
      velocity="9" />
  </joint>
  <link
    name="right_knee_link">
    <inertial>
      <origin
        xyz="0.0035375 0.030016 -0.12581"
        rpy="0 0 0" />
      <mass
        value="2.7384" />
      <inertia
        ixx="0.018175"
        ixy="3.7377E-06"
        ixz="0.00066618"
        iyy="0.019344"
        iyz="1.9227E-05"
        izz="0.0016642" />
    </inertial>
    <visual>
      <origin
        xyz="0 0 0"
        rpy="0 0 0" />
      <geometry>
        <mesh
          filename="../meshes/right_knee_link.STL" />
      </geometry>
      <material
        name="">
        <color
          rgba="0.89804 0.91765 0.92941 1" />
      </material>
    </visual>
    <!-- <collision>
      <origin
        xyz="0 0 0"
        rpy="0 0 0" />
      <geometry>
        <mesh
          filename="../meshes/right_knee_link.STL" />
      </geometry>
    </collision> -->
  </link>
  <joint
    name="right_knee_joint"
    type="revolute">
    <origin
      xyz="0 -0.02 -0.4151"
      rpy="0 0 0" />
    <parent
      link="right_leg_yaw_link" />
    <child
      link="right_knee_link" />
    <axis
      xyz="0 1 0" />
    <limit
      lower="-0.7"
      upper="1.5"
      effort="250"
      velocity="9" />
  </joint>
  <link
    name="right_ankle_pitch_link">
    <inertial>
      <origin
        xyz="1.2848E-09 0.0307 -2.8828E-10"
        rpy="0 0 0" />
      <mass
        value="0.10749" />
      <inertia
        ixx="1.4354E-05"
        ixy="2.6541E-14"
        ixz="-6.658E-13"
        iyy="1.4339E-05"
        iyz="-6.3545E-13"
        izz="1.6257E-05" />
    </inertial>
    <visual>
      <origin
        xyz="0 0 0"
        rpy="0 0 0" />
      <geometry>
        <mesh
          filename="../meshes/right_ankle_pitch_link.STL" />
      </geometry>
      <material
        name="">
        <color
          rgba="0.89804 0.91765 0.92941 1" />
      </material>
    </visual>
    <!-- <collision>
      <origin
        xyz="0 0 0"
        rpy="0 0 0" />
      <geometry>
        <mesh
          filename="../meshes/right_ankle_pitch_link.STL" />
      </geometry>
    </collision> -->
  </link>
  <joint
    name="right_ankle_pitch_joint"
    type="revolute">
    <origin
      xyz="0.015 -0.0007 -0.37"
      rpy="0 0 0" />
    <parent
      link="right_knee_link" />
    <child
      link="right_ankle_pitch_link" />
    <axis
      xyz="0 -1 0" />
    <limit
      lower="-0.7"
      upper="0.87"
      effort="100"
      velocity="9" />
    <dynamics
      friction="0.1" />
  </joint>
  <link
    name="right_ankle_roll_link">
    <inertial>
      <origin
        xyz="-0.0307 0.00016219 -0.027162"
        rpy="0 0 0" />
      <mass
        value="0.14038" />
      <inertia
        ixx="5.7884E-05"
        ixy="-5.1703E-11"
        ixz="4.1473E-10"
        iyy="9.3946E-05"
        iyz="1.0763E-07"
        izz="7.4507E-05" />
    </inertial>
    <visual>
      <origin
        xyz="0 0 0"
        rpy="0 0 0" />
      <geometry>
        <mesh
          filename="../meshes/right_ankle_roll_link.STL" />
      </geometry>
      <material
        name="">
        <color
          rgba="0.89804 0.91765 0.92941 1" />
      </material>
    </visual>
    <!-- <collision>
      <origin
        xyz="0 0 0"
        rpy="0 0 0" />
      <geometry>
        <mesh
          filename="../meshes/right_ankle_roll_link.STL" />
      </geometry>
    </collision> -->
  </link>
  <joint
    name="right_ankle_roll_joint"
    type="revolute">
    <origin
      xyz="0.0307 0.0307 0"
      rpy="0 0 0" />
    <parent
      link="right_ankle_pitch_link" />
    <child
      link="right_ankle_roll_link" />
    <axis
      xyz="1 0 0" />
    <limit
      lower="-0.5"
      upper="0.5"
      effort="100"
      velocity="9" />
    <dynamics
      friction="0.1" />
  </joint>
  <link
    name="R_foot">
    <inertial>
      <origin
        xyz="0.016486 -3.9561E-06 0.0059825"
        rpy="0 0 0" />
      <mass
        value="0.58366" />
      <inertia
        ixx="0.00043428"
        ixy="2.1966E-07"
        ixz="1.6375E-06"
        iyy="0.0025408"
        iyz="1.4886E-09"
        izz="0.0029617" />
    </inertial>
    <visual>
      <origin
        xyz="0 0 0"
        rpy="0 0 0" />
      <geometry>
        <mesh
          filename="../meshes/R_foot.STL" />
      </geometry>
      <material
        name="">
        <color
          rgba="0.89804 0.91765 0.92941 1" />
      </material>
    </visual>
    <collision>
      <origin
        xyz="0.07 0.0 0.0"
        rpy="0 0 0" />
      <geometry>
        <box size="0.35 0.10 0.02"/>
      </geometry>
    </collision>
  </link>
  <joint
    name="R_foot_joint"
    type="fixed">
    <origin
      xyz="-0.0307 0 -0.0730000000000002"
      rpy="0 0 0" />
    <parent
      link="right_ankle_roll_link" />
    <child
      link="R_foot" />
    <axis
      xyz="0 0 0" />
  </joint>
</robot>